{"trial_id": "0000", "hyperparameters": {"space": [{"class_name": "Choice", "config": {"name": "activation", "default": "relu", "conditions": [], "values": ["relu", "tanh", "sigmoid"], "ordered": false}}, {"class_name": "Int", "config": {"name": "first_units", "default": null, "conditions": [], "min_value": 1, "max_value": 10, "step": 2, "sampling": "linear"}}, {"class_name": "Int", "config": {"name": "num_layers", "default": null, "conditions": [], "min_value": 1, "max_value": 6, "step": 1, "sampling": "linear"}}, {"class_name": "Int", "config": {"name": "units_0", "default": null, "conditions": [], "min_value": 1, "max_value": 10, "step": 2, "sampling": "linear"}}], "values": {"activation": "sigmoid", "first_units": 3, "num_layers": 1, "units_0": 9, "tuner/epochs": 2, "tuner/initial_epoch": 0, "tuner/bracket": 4, "tuner/round": 0}}, "metrics": {"metrics": {}}, "score": null, "best_step": 0, "status": "FAILED", "message": "Traceback (most recent call last):\n  File \"C:\\Users\\patri\\anaconda3\\lib\\site-packages\\keras_tuner\\engine\\base_tuner.py\", line 250, in _try_run_and_update_trial\n    self._run_and_update_trial(trial, *fit_args, **fit_kwargs)\n  File \"C:\\Users\\patri\\anaconda3\\lib\\site-packages\\keras_tuner\\engine\\base_tuner.py\", line 215, in _run_and_update_trial\n    results = self.run_trial(trial, *fit_args, **fit_kwargs)\n  File \"C:\\Users\\patri\\anaconda3\\lib\\site-packages\\keras_tuner\\tuners\\hyperband.py\", line 401, in run_trial\n    return super().run_trial(trial, *fit_args, **fit_kwargs)\n  File \"C:\\Users\\patri\\anaconda3\\lib\\site-packages\\keras_tuner\\engine\\tuner.py\", line 284, in run_trial\n    obj_value = self._build_and_fit_model(trial, *args, **copied_kwargs)\n  File \"C:\\Users\\patri\\anaconda3\\lib\\site-packages\\keras_tuner\\engine\\tuner.py\", line 211, in _build_and_fit_model\n    results = self.hypermodel.fit(hp, model, *args, **kwargs)\n  File \"C:\\Users\\patri\\anaconda3\\lib\\site-packages\\keras_tuner\\engine\\hypermodel.py\", line 142, in fit\n    return model.fit(*args, **kwargs)\n  File \"C:\\Users\\patri\\anaconda3\\lib\\site-packages\\keras\\utils\\traceback_utils.py\", line 70, in error_handler\n    raise e.with_traceback(filtered_tb) from None\n  File \"C:\\Users\\patri\\AppData\\Local\\Temp\\__autograph_generated_file9o03g2d7.py\", line 15, in tf__train_function\n    retval_ = ag__.converted_call(ag__.ld(step_function), (ag__.ld(self), ag__.ld(iterator)), None, fscope)\nValueError: in user code:\n\n    File \"C:\\Users\\patri\\anaconda3\\lib\\site-packages\\keras\\engine\\training.py\", line 1249, in train_function  *\n        return step_function(self, iterator)\n    File \"C:\\Users\\patri\\anaconda3\\lib\\site-packages\\keras\\engine\\training.py\", line 1233, in step_function  **\n        outputs = model.distribute_strategy.run(run_step, args=(data,))\n    File \"C:\\Users\\patri\\anaconda3\\lib\\site-packages\\keras\\engine\\training.py\", line 1222, in run_step  **\n        outputs = model.train_step(data)\n    File \"C:\\Users\\patri\\anaconda3\\lib\\site-packages\\keras\\engine\\training.py\", line 1023, in train_step\n        y_pred = self(x, training=True)\n    File \"C:\\Users\\patri\\anaconda3\\lib\\site-packages\\keras\\utils\\traceback_utils.py\", line 70, in error_handler\n        raise e.with_traceback(filtered_tb) from None\n    File \"C:\\Users\\patri\\anaconda3\\lib\\site-packages\\keras\\engine\\input_spec.py\", line 295, in assert_input_compatibility\n        raise ValueError(\n\n    ValueError: Input 0 of layer \"sequential\" is incompatible with the layer: expected shape=(None, 2), found shape=(None, 41)\n\n"}